<sdf version='1.6'>
  <model name='r1_rover'>
    <link name='base_link'>
      <pose>0 0 0 0 -0 0</pose>
      <inertial>
        <pose>0 0 0 0 -0 0</pose>
        <mass>20.0</mass>
        <inertia>
          <ixx>0.37083</ixx>
          <ixy>0.0</ixy>
          <ixz>0.0</ixz>
          <iyy>0.37083</iyy>
          <iyz>0.0</iyz>
          <izz>0.53333</izz>
        </inertia>
      </inertial>
      <collision name='odom_fixed_joint_lump__base_link_collision'>
        <pose>0 0 0.15 0 -0 0</pose>
        <geometry>
          <box>
            <size>0.4 0.4 0.25</size>
          </box>
        </geometry>
        <surface>
          <contact>
            <ode />
          </contact>
          <friction>
            <ode />
          </friction>
        </surface>
      </collision>
      <visual name='odom_fixed_joint_lump__base_link_visual'>
        <pose>0 0 0 0 -0 0</pose>
        <geometry>
          <mesh>
            <scale>1 1 1</scale>
            <uri>model://r1_rover/meshes/chassis_link.STL</uri>
          </mesh>
        </geometry>
        <material>
          <diffuse>1.0 0.0 0.0 1.0</diffuse>
          <specular>1.0 0.0 0.0 1.0</specular>
        </material>
      </visual>
      <visual name='odom_fixed_joint_lump__top_link_visual_1'>
        <pose>0 0 0.114486 0 -0 0</pose>
        <geometry>
          <mesh>
            <scale>1 1 1</scale>
            <uri>model://r1_rover/meshes/top_link.STL</uri>
          </mesh>
        </geometry>
        <material>
          <diffuse>1.0 0.0 0.0 1.0</diffuse>
          <specular>1.0 0.0 0.0 1.0</specular>
        </material>
      </visual>
      <visual name='odom_fixed_joint_lump__battery_link_visual_2'>
        <pose>-0.09302 -0.000128 0.114486 0 -0 0</pose>
        <geometry>
          <mesh>
            <scale>1 1 1</scale>
            <uri>model://r1_rover/meshes/battery_link.STL</uri>
          </mesh>
        </geometry>
        <material>
          <diffuse>1.0 0.0 0.0 1.0</diffuse>
          <specular>0.5 0.5 0.5 1.0</specular>
        </material>
      </visual>
      <visual name='odom_fixed_joint_lump__housing_link_visual_3'>
        <pose>0.03473 0 0.114486 0 -0 0</pose>
        <geometry>
          <mesh>
            <scale>1 1 1</scale>
            <uri>model://r1_rover/meshes/housing_link.STL</uri>
          </mesh>
        </geometry>
        <material>
          <diffuse>1.0 0.0 0.0 1.0</diffuse>
          <specular>0.5 0.5 0.5 1.0</specular>
        </material>
      </visual>
      <visual name='odom_fixed_joint_lump__l_antenna_link_visual_4'>
        <pose>-0.1565 0.0762 0.114486 0 -0 0</pose>
        <geometry>
          <mesh>
            <scale>1 1 1</scale>
            <uri>model://r1_rover/meshes/antenna_link.STL</uri>
          </mesh>
        </geometry>
        <material>
          <diffuse>1.0 0.0 0.0 1.0</diffuse>
          <specular>0.5 0.5 0.5 1.0</specular>
        </material>
      </visual>
      <visual name='odom_fixed_joint_lump__r_antenna_link_visual_5'>
        <pose>-0.1565 -0.0762 0.114486 0 -0 0</pose>
        <geometry>
          <mesh>
            <scale>1 1 1</scale>
            <uri>model://r1_rover/meshes/antenna_link.STL</uri>
          </mesh>
        </geometry>
        <material>
          <diffuse>1.0 0.0 0.0 1.0</diffuse>
          <specular>0.5 0.5 0.5 1.0</specular>
        </material>
      </visual>
      <gravity>1</gravity>
      <sensor name="imu_sensor" type="imu">
        <gz_frame_id>base_link</gz_frame_id>
        <always_on>1</always_on>
        <update_rate>250</update_rate>
        <imu/>
      </sensor>
      <sensor name="camera_front" type="camera">
  <pose>0.2 0 0.25 0 0 0</pose> <always_on>1</always_on>
  <update_rate>30</update_rate>
  <visualize>true</visualize>
  <topic>/model/r1/camera</topic>
  <camera>
    <horizontal_fov>1.047</horizontal_fov>
    <image>
      <width>640</width>
      <height>480</height>
      <format>R8G8B8</format>
    </image>
    <clip>
      <near>0.1</near>
      <far>100</far>
    </clip>
  </camera>
</sensor>
    </link>

    <link name='lf_wheel_link'>
      <pose>0.15 0.16317 0.0215 0 -0 0</pose>
      <inertial>
        <pose>0 0 0 1.57079632679 0 0</pose>
        <mass>0.414</mass>
        <inertia>
          <ixx>0.00068682</ixx><ixy>0</ixy><ixz>0</ixz>
          <iyy>0.00068682</iyy><iyz>0</iyz><izz>0.00097299</izz>
        </inertia>
      </inertial>
      <collision name='lf_wheel_link_collision'>
        <pose>0 0 0 1.57079632679 0 0</pose>
        <geometry>
          <cylinder><radius>0.0686</radius><length>0.0762</length></cylinder>
        </geometry>
      </collision>
      <visual name='lf_wheel_link_visual'>
        <geometry>
          <mesh><uri>model://r1_rover/meshes/wheel_link.STL</uri></mesh>
        </geometry>
        <material><diffuse>0 0 0 1</diffuse></material>
      </visual>
    </link>

    <link name='lb_wheel_link'>
      <pose>-0.15 0.16317 0.0215 0 -0 0</pose>
      <inertial>
        <pose>0 0 0 1.57079632679 0 0</pose>
        <mass>0.414</mass>
        <inertia>
          <ixx>0.00068682</ixx><ixy>0</ixy><ixz>0</ixz>
          <iyy>0.00068682</iyy><iyz>0</iyz><izz>0.00097299</izz>
        </inertia>
      </inertial>
      <collision name='lb_wheel_link_collision'>
        <pose>0 0 0 1.57079632679 0 0</pose>
        <geometry>
          <cylinder><radius>0.0686</radius><length>0.0762</length></cylinder>
        </geometry>
      </collision>
      <visual name='lb_wheel_link_visual'>
        <geometry>
          <mesh><uri>model://r1_rover/meshes/wheel_link.STL</uri></mesh>
        </geometry>
        <material><diffuse>0 0 0 1</diffuse></material>
      </visual>
    </link>

    <link name='rf_wheel_link'>
      <pose>0.15 -0.16317 0.0215 0 -0 0</pose>
      <inertial>
        <pose>0 0 0 1.57079632679 0 0</pose>
        <mass>0.414</mass>
        <inertia>
          <ixx>0.00068682</ixx><ixy>0</ixy><ixz>0</ixz>
          <iyy>0.00068682</iyy><iyz>0</iyz><izz>0.00097299</izz>
        </inertia>
      </inertial>
      <collision name='rf_wheel_link_collision'>
        <pose>0 0 0 1.57079632679 0 0</pose>
        <geometry>
          <cylinder><radius>0.0686</radius><length>0.0762</length></cylinder>
        </geometry>
      </collision>
      <visual name='rf_wheel_link_visual'>
        <geometry>
          <mesh><uri>model://r1_rover/meshes/wheel_link.STL</uri></mesh>
        </geometry>
        <material><diffuse>0 0 0 1</diffuse></material>
      </visual>
    </link>

    <link name='rb_wheel_link'>
      <pose>-0.15 -0.16317 0.0215 0 -0 0</pose>
      <inertial>
        <pose>0 0 0 1.57079632679 0 0</pose>
        <mass>0.414</mass>
        <inertia>
          <ixx>0.00068682</ixx><ixy>0</ixy><ixz>0</ixz>
          <iyy>0.00068682</iyy><iyz>0</iyz><izz>0.00097299</izz>
        </inertia>
      </inertial>
      <collision name='rb_wheel_link_collision'>
        <pose>0 0 0 1.57079632679 0 0</pose>
        <geometry>
          <cylinder><radius>0.0686</radius><length>0.0762</length></cylinder>
        </geometry>
      </collision>
      <visual name='rb_wheel_link_visual'>
        <geometry>
          <mesh><uri>model://r1_rover/meshes/wheel_link.STL</uri></mesh>
        </geometry>
        <material><diffuse>0 0 0 1</diffuse></material>
      </visual>
    </link>

    <joint name='motor_0' type='revolute'>
      <child>lf_wheel_link</child>
      <parent>base_link</parent>
      <axis><xyz>0 1 0</xyz></axis>
    </joint>
    <joint name='motor_1' type='revolute'>
      <child>lb_wheel_link</child>
      <parent>base_link</parent>
      <axis><xyz>0 1 0</xyz></axis>
    </joint>
    <joint name='motor_2' type='revolute'>
      <child>rf_wheel_link</child>
      <parent>base_link</parent>
      <axis><xyz>0 1 0</xyz></axis>
    </joint>
    <joint name='motor_3' type='revolute'>
      <child>rb_wheel_link</child>
      <parent>base_link</parent>
      <axis><xyz>0 1 0</xyz></axis>
    </joint>

    <static>0</static>
<plugin
  filename="gz-sim-diff-drive-system"
  name="gz::sim::systems::DiffDrive">

  <left_joint>motor_0</left_joint>
  <left_joint>motor_1</left_joint>

  <right_joint>motor_2</right_joint>
  <right_joint>motor_3</right_joint>

  <wheel_separation>0.326</wheel_separation> <wheel_radius>0.0686</wheel_radius> <topic>/model/r1/cmd_vel</topic>
</plugin>
<plugin
  filename="gz-sim-sensors-system"
  name="gz::sim::systems::Sensors">
  <render_engine>ogre2</render_engine>
</plugin>
  </model>

</sdf>